<mujoco model="diff drive lidar">
	<option gravity="0 0 -9.81" />
	<visual>
		<rgba rangefinder="1 1 0.1 0.1"/>
		<map znear=".005" zfar="20"/>
	</visual>
	<worldbody>
		<!-- Define the general arena -->
		<light diffuse=".5 .5 .5" pos="0 0 3" dir="0 0 -1"/>
		<!-- Load in the walls and obstacles: -->
		<include name="s" file="currentxml.xml" resolve_relative="base" /> 
		<!-- <!-1- Leaving walls out creates some issues, the cut-off value in lidar.xml needs something to be hit. -1-> -->
		<geom name="left_wall" type="box" size="0.1 50 1" pos="-30 0 1" euler = "0 0 -0" rgba="0.8 0.2 0.2 1" />
		<geom name="right_wall" type="box" size="0.1 50 1" pos="25 0 1" euler = "0 0 -0" rgba="0.2 0.8 0.2 1" />
		<geom name="top_wall" type="box" size="50 0.1  1" pos="0 30 1" rgba="0.8 0.2 0.2 1" />
		<geom name="bottom_wall" type="box" size="50 0.1 1" pos=" 0 -30 1" rgba="0.2 0.8 0.2 1" />

		<geom type="plane" size="50 50 0.1" rgba=".9 .9 .9 1"/>



		<!-- Define the chassis, which loads in the LiDAR frame: -->
		<body name = "chassis" pos="0 4 0.2" euler='0 0 0'>
			<joint type="free"/>
			<geom type="box" size=".2 .2 .05" rgba=".9 .9 0 1"/>
			<site name="marker" pos = "0.0 0 0.2 " size="0.1" />
			<body name="sphereWheel" pos = "-0.3 0 -0.1" euler = "0 0 0">

				<joint name = "sphere-wheel" type="ball" axis="0 0 -1"/>
				<geom type="sphere" size="0.1" rgba="0 .9 0 1"/>
			</body>
			<body name="left-tire" pos="0 0.3 -0.0" euler='90 0 0'>
				<joint name = "left-wheel" type="hinge" axis="0 0 -1"/>
				<geom type="cylinder" size=".2 0.05" rgba="0 .9 0 1"/>
			</body>
			<body name="right-tire" pos="0 -0.3 -0.0" euler='90 0 0'>
				<joint name = "right-wheel" type="hinge" axis="0 0 -1"/>
				<geom type="cylinder" size=".2 0.05" rgba="0 .9 0 1"/>
			</body>
			<!-- The LiDAR frame contains 360 slightly rotated frames, within which we later place a rangefinder: -->
			<include name="s" file="lidar_frame.xml" resolve_relative="base" />

		</body>
	</worldbody>
	<!--Place rangefinder sensors in the frames defined in lidar_frame.xml: -->
	<include name="s" file="lidar.xml" resolve_relative="base" />

	<sensor>
		<framepos objtype="site" objname="marker"/>
		<framequat objtype="site" objname="marker"/>
	</sensor>
	<actuator>
		<velocity name="left-velocity-servo" joint="left-wheel" kv="100"/>
		<velocity name="right-velocity-servo" joint="right-wheel" kv="100"/>
	</actuator>
</mujoco>
